<?xml version="1.0" ?>
<!-- =================================================================================== -->
<!-- |    This document was autogenerated by xacro from mobile_robot10.xacro           | -->
<!-- |    EDITING THIS FILE BY HAND IS NOT RECOMMENDED                                 | -->
<!-- =================================================================================== -->
<robot name="mobile_robot10">
  <material name="silver">
    <color rgba="0.700 0.700 0.700 1.000"/>
  </material>
  <transmission name="revLB_tran">
    <type>transmission_interface/SimpleTransmission</type>
    <joint name="revLB">
      <hardwareInterface>hardware_interface/EffortJointInterface</hardwareInterface>
    </joint>
    <actuator name="revLB_actr">
      <hardwareInterface>hardware_interface/EffortJointInterface</hardwareInterface>
      <mechanicalReduction>1</mechanicalReduction>
    </actuator>
  </transmission>
  <transmission name="revLF_tran">
    <type>transmission_interface/SimpleTransmission</type>
    <joint name="revLF">
      <hardwareInterface>hardware_interface/EffortJointInterface</hardwareInterface>
    </joint>
    <actuator name="revLF_actr">
      <hardwareInterface>hardware_interface/EffortJointInterface</hardwareInterface>
      <mechanicalReduction>1</mechanicalReduction>
    </actuator>
  </transmission>
  <transmission name="revRF_tran">
    <type>transmission_interface/SimpleTransmission</type>
    <joint name="revRF">
      <hardwareInterface>hardware_interface/EffortJointInterface</hardwareInterface>
    </joint>
    <actuator name="revRF_actr">
      <hardwareInterface>hardware_interface/EffortJointInterface</hardwareInterface>
      <mechanicalReduction>1</mechanicalReduction>
    </actuator>
  </transmission>
  <transmission name="revRB_tran">
    <type>transmission_interface/SimpleTransmission</type>
    <joint name="revRB">
      <hardwareInterface>hardware_interface/EffortJointInterface</hardwareInterface>
    </joint>
    <actuator name="revRB_actr">
      <hardwareInterface>hardware_interface/EffortJointInterface</hardwareInterface>
      <mechanicalReduction>1</mechanicalReduction>
    </actuator>
  </transmission>
  <gazebo>
    <plugin name="gazebo_ros_control" filename="libgazebo_ros_control.so">
      <robotNamespace>mobile_robot10</robotNamespace>
    </plugin>

    <plugin name="base_move" filename="libgazebo_ros_force_based_move.so">
      <robotNamespace>mobile_robot10</robotNamespace>
      <commandTopic>cmd_vel</commandTopic>
      <odometryTopic>odom</odometryTopic>
      <odometryFrame>odom</odometryFrame>
      <odometryRate>25.0</odometryRate>
      <robotBaseFrame>base_link</robotBaseFrame>
      <cmdVelTimeOut>0.25</cmdVelTimeOut>
      <publishOdometry>true</publishOdometry>
      <publishOdometryTf>true</publishOdometryTf>
      <yaw_velocity_p_gain>500.0</yaw_velocity_p_gain>
      <x_velocity_p_gain>10000.0</x_velocity_p_gain>
      <y_velocity_p_gain>10000.0</y_velocity_p_gain>
    </plugin> 
  </gazebo>
  
  <gazebo reference="lidar_1">
    <sensor name="head_hokuyo_sensor" type="ray">
      <pose>0 0 0 0 0 0</pose>
      <visualize>false</visualize>
      <update_rate>20</update_rate>
      <ray>
        <scan>
          <horizontal>
            <samples>720</samples>
            <resolution>1</resolution>
            <min_angle>-3.14</min_angle>
            <max_angle>3.14</max_angle>
          </horizontal>
        </scan>
        <range>
          <min>0.50</min>
          <max>20.0</max>
          <resolution>0.01</resolution>
        </range>
        <noise>
          <type>gaussian</type>
          <!-- Noise parameters based on published spec for Hokuyo laser
               achieving "+-30mm" accuracy at range < 10m.  A mean of 0.0m and
               stddev of 0.01m will put 99.7% of samples within 0.03m of the true
               reading. -->
          <mean>0.0</mean>
          <stddev>0.01</stddev>
        </noise>
      </ray>
      <plugin filename="libgazebo_ros_laser.so" name="gazebo_ros_head_hokuyo_controller">
        <topicName>/rrbot/laser/scan</topicName>
        <frameName>lidar_1</frameName>
      </plugin>
    </sensor>
  </gazebo>
  <gazebo>
    <plugin filename="libgazebo_ros_control.so" name="control"/>
  </gazebo>
  <gazebo reference="base_link">
    <material>Gazebo/Silver</material>
    <mu1>0.2</mu1>
    <mu2>0.2</mu2>
    <selfCollide>true</selfCollide>
    <gravity>true</gravity>
  </gazebo>
  <gazebo reference="motor_RightBack_1">
    <material>Gazebo/Silver</material>
    <mu1>0.2</mu1>
    <mu2>0.2</mu2>
    <selfCollide>true</selfCollide>
  </gazebo>
  <gazebo reference="motor_RightFront_1">
    <material>Gazebo/Silver</material>
    <mu1>0.2</mu1>
    <mu2>0.2</mu2>
    <selfCollide>true</selfCollide>
  </gazebo>
  <gazebo reference="motor_LeftFront_1">
    <material>Gazebo/Silver</material>
    <mu1>0.2</mu1>
    <mu2>0.2</mu2>
    <selfCollide>true</selfCollide>
  </gazebo>
  <gazebo reference="motor_LeftBack_1">
    <material>Gazebo/Silver</material>
    <mu1>0.2</mu1>
    <mu2>0.2</mu2>
    <selfCollide>true</selfCollide>
  </gazebo>
  <gazebo reference="wheel_LeftBack_1">
    <material>Gazebo/Silver</material>
    <mu1>0.2</mu1>
    <mu2>0.2</mu2>
    <selfCollide>true</selfCollide>
  </gazebo>
  <gazebo reference="wheel_LeftFront_1">
    <material>Gazebo/Silver</material>
    <mu1>0.2</mu1>
    <mu2>0.2</mu2>
    <selfCollide>true</selfCollide>
  </gazebo>
  <gazebo reference="wheel_RightFront_1">
    <material>Gazebo/Silver</material>
    <mu1>0.2</mu1>
    <mu2>0.2</mu2>
    <selfCollide>true</selfCollide>
  </gazebo>
  <gazebo reference="wheel_RightBack_1">
    <material>Gazebo/Silver</material>
    <mu1>0.2</mu1>
    <mu2>0.2</mu2>
    <selfCollide>true</selfCollide>
  </gazebo>
  <gazebo reference="lidar_1">
    <material>Gazebo/Silver</material>
    <mu1>0.2</mu1>
    <mu2>0.2</mu2>
    <selfCollide>true</selfCollide>
  </gazebo>
  <link name="base_link">
    <inertial>
      <origin rpy="0 0 0" xyz="0.0020658010069307346 0.0014540542329803576 0.13278563199845814"/>
      <mass value="4.254378190431725"/>
      <inertia ixx="0.111017" ixy="5e-06" ixz="-2e-06" iyy="0.100165" iyz="-0.0" izz="0.193805"/>
    </inertial>
    <visual>
      <origin rpy="0 0 0" xyz="0 0 0"/>
      <geometry>
        <mesh filename="package://mobile_robot10_description/meshes/base_link.stl" scale="0.001 0.001 0.001"/>
      </geometry>
      <material name="silver"/>
    </visual>
    <collision>
      <origin rpy="0 0 0" xyz="0 0 0"/>
      <geometry>
        <mesh filename="package://mobile_robot10_description/meshes/base_link.stl" scale="0.001 0.001 0.001"/>
      </geometry>
    </collision>
  </link>
  <link name="motor_RightBack_1">
    <inertial>
      <origin rpy="0 0 0" xyz="2.3547808934085146e-05 0.03723394965455805 -6.253738071324011e-06"/>
      <mass value="0.24966798972825235"/>
      <inertia ixx="0.000251" ixy="0.0" ixz="-0.0" iyy="0.000108" iyz="-0.0" izz="0.000251"/>
    </inertial>
    <visual>
      <origin rpy="0 0 0" xyz="0.118927 0.124046 -0.090327"/>
      <geometry>
        <mesh filename="package://mobile_robot10_description/meshes/motor_RightBack_1.stl" scale="0.001 0.001 0.001"/>
      </geometry>
      <material name="silver"/>
    </visual>
    <collision>
      <origin rpy="0 0 0" xyz="0.118927 0.124046 -0.090327"/>
      <geometry>
        <mesh filename="package://mobile_robot10_description/meshes/motor_RightBack_1.stl" scale="0.001 0.001 0.001"/>
      </geometry>
    </collision>
  </link>
  <link name="motor_RightFront_1">
    <inertial>
      <origin rpy="0 0 0" xyz="2.3547808934029635e-05 0.03723394965455806 -6.253738070879922e-06"/>
      <mass value="0.24966798972825235"/>
      <inertia ixx="0.000251" ixy="0.0" ixz="-0.0" iyy="0.000108" iyz="-0.0" izz="0.000251"/>
    </inertial>
    <visual>
      <origin rpy="0 0 0" xyz="-0.123073 0.124046 -0.090327"/>
      <geometry>
        <mesh filename="package://mobile_robot10_description/meshes/motor_RightFront_1.stl" scale="0.001 0.001 0.001"/>
      </geometry>
      <material name="silver"/>
    </visual>
    <collision>
      <origin rpy="0 0 0" xyz="-0.123073 0.124046 -0.090327"/>
      <geometry>
        <mesh filename="package://mobile_robot10_description/meshes/motor_RightFront_1.stl" scale="0.001 0.001 0.001"/>
      </geometry>
    </collision>
  </link>
  <link name="motor_LeftFront_1">
    <inertial>
      <origin rpy="0 0 0" xyz="2.354780893325248e-05 -0.03723384118858371 5.98091283564306e-06"/>
      <mass value="0.24966798972825235"/>
      <inertia ixx="0.000251" ixy="-0.0" ixz="0.0" iyy="0.000108" iyz="-0.0" izz="0.000251"/>
    </inertial>
    <visual>
      <origin rpy="0 0 0" xyz="-0.123073 -0.126954 -0.090327"/>
      <geometry>
        <mesh filename="package://mobile_robot10_description/meshes/motor_LeftFront_1.stl" scale="0.001 0.001 0.001"/>
      </geometry>
      <material name="silver"/>
    </visual>
    <collision>
      <origin rpy="0 0 0" xyz="-0.123073 -0.126954 -0.090327"/>
      <geometry>
        <mesh filename="package://mobile_robot10_description/meshes/motor_LeftFront_1.stl" scale="0.001 0.001 0.001"/>
      </geometry>
    </collision>
  </link>
  <link name="motor_LeftBack_1">
    <inertial>
      <origin rpy="0 0 0" xyz="2.354780893312758e-05 -0.03723384118858267 5.980912835740204e-06"/>
      <mass value="0.24966798972825235"/>
      <inertia ixx="0.000251" ixy="-0.0" ixz="0.0" iyy="0.000108" iyz="-0.0" izz="0.000251"/>
    </inertial>
    <visual>
      <origin rpy="0 0 0" xyz="0.118927 -0.126954 -0.090327"/>
      <geometry>
        <mesh filename="package://mobile_robot10_description/meshes/motor_LeftBack_1.stl" scale="0.001 0.001 0.001"/>
      </geometry>
      <material name="silver"/>
    </visual>
    <collision>
      <origin rpy="0 0 0" xyz="0.118927 -0.126954 -0.090327"/>
      <geometry>
        <mesh filename="package://mobile_robot10_description/meshes/motor_LeftBack_1.stl" scale="0.001 0.001 0.001"/>
      </geometry>
    </collision>
  </link>
  <link name="wheel_LeftBack_1">
    <inertial>
      <origin rpy="0 0 0" xyz="-0.0002211856349259439 0.09160029831890285 0.00011976017282845641"/>
      <mass value="0.23076924157480921"/>
      <inertia ixx="0.000435" ixy="1e-06" ixz="0.0" iyy="0.000747" iyz="-1e-06" izz="0.000435"/>
    </inertial>
    <visual>
      <origin rpy="0 0 0" xyz="0.118915 -0.169604 -0.090327"/>
      <geometry>
        <mesh filename="package://mobile_robot10_description/meshes/wheel_LeftBack_1.stl" scale="0.001 0.001 0.001"/>
      </geometry>
      <material name="silver"/>
    </visual>
    <collision>
      <origin rpy="0 0 0" xyz="0.118915 -0.169604 -0.090327"/>
      <geometry>
        <mesh filename="package://mobile_robot10_description/meshes/wheel_LeftBack_1.stl" scale="0.001 0.001 0.001"/>
      </geometry>
    </collision>
  </link>
  <link name="wheel_LeftFront_1">
    <inertial>
      <origin rpy="0 0 0" xyz="-5.743380377766505e-05 0.09191036254399113 0.00012495117271071887"/>
      <mass value="0.2305439882563863"/>
      <inertia ixx="0.000437" ixy="0.0" ixz="0.0" iyy="0.000748" iyz="-1e-06" izz="0.000437"/>
    </inertial>
    <visual>
      <origin rpy="0 0 0" xyz="-0.123073 -0.169604 -0.090327"/>
      <geometry>
        <mesh filename="package://mobile_robot10_description/meshes/wheel_LeftFront_1.stl" scale="0.001 0.001 0.001"/>
      </geometry>
      <material name="silver"/>
    </visual>
    <collision>
      <origin rpy="0 0 0" xyz="-0.123073 -0.169604 -0.090327"/>
      <geometry>
        <mesh filename="package://mobile_robot10_description/meshes/wheel_LeftFront_1.stl" scale="0.001 0.001 0.001"/>
      </geometry>
    </collision>
  </link>
  <link name="wheel_RightFront_1">
    <inertial>
      <origin rpy="0 0 0" xyz="-0.00022118563492501409 -0.09160018985292717 -0.00012003299806354062"/>
      <mass value="0.23076924157480921"/>
      <inertia ixx="0.000435" ixy="-1e-06" ixz="-0.0" iyy="0.000747" iyz="-1e-06" izz="0.000435"/>
    </inertial>
    <visual>
      <origin rpy="0 0 0" xyz="-0.123085 0.166696 -0.090327"/>
      <geometry>
        <mesh filename="package://mobile_robot10_description/meshes/wheel_RightFront_1.stl" scale="0.001 0.001 0.001"/>
      </geometry>
      <material name="silver"/>
    </visual>
    <collision>
      <origin rpy="0 0 0" xyz="-0.123085 0.166696 -0.090327"/>
      <geometry>
        <mesh filename="package://mobile_robot10_description/meshes/wheel_RightFront_1.stl" scale="0.001 0.001 0.001"/>
      </geometry>
    </collision>
  </link>
  <link name="wheel_RightBack_1">
    <inertial>
      <origin rpy="0 0 0" xyz="-5.719253608364727e-05 -0.09191025407801684 -0.0001251999899373052"/>
      <mass value="0.2305439882563863"/>
      <inertia ixx="0.000437" ixy="-0.0" ixz="-0.0" iyy="0.000748" iyz="-1e-06" izz="0.000437"/>
    </inertial>
    <visual>
      <origin rpy="0 0 0" xyz="0.118915 0.166696 -0.090327"/>
      <geometry>
        <mesh filename="package://mobile_robot10_description/meshes/wheel_RightBack_1.stl" scale="0.001 0.001 0.001"/>
      </geometry>
      <material name="silver"/>
    </visual>
    <collision>
      <origin rpy="0 0 0" xyz="0.118915 0.166696 -0.090327"/>
      <geometry>
        <mesh filename="package://mobile_robot10_description/meshes/wheel_RightBack_1.stl" scale="0.001 0.001 0.001"/>
      </geometry>
    </collision>
  </link>
  <link name="lidar_1">
    <inertial>
      <origin rpy="0 0 0" xyz="1.9045593262516022e-07 5.4232985110353946e-08 0.012499863587381699"/>
      <mass value="1.541343895667494"/>
      <inertia ixx="0.001044" ixy="0.0" ixz="-0.0" iyy="0.001044" iyz="-0.0" izz="0.001927"/>
    </inertial>
    <visual>
      <origin rpy="0 0 0" xyz="-0.002073 -0.001454 -0.181327"/>
      <geometry>
        <mesh filename="package://mobile_robot10_description/meshes/lidar_1.stl" scale="0.001 0.001 0.001"/>
      </geometry>
      <material name="silver"/>
    </visual>
    <collision>
      <origin rpy="0 0 0" xyz="-0.002073 -0.001454 -0.181327"/>
      <geometry>
        <mesh filename="package://mobile_robot10_description/meshes/lidar_1.stl" scale="0.001 0.001 0.001"/>
      </geometry>
    </collision>
  </link>
  <joint name="Rigid 23" type="fixed">
    <origin rpy="0 0 0" xyz="-0.118927 -0.124046 0.090327"/>
    <parent link="base_link"/>
    <child link="motor_RightBack_1"/>
  </joint>
  <joint name="Rigid 24" type="fixed">
    <origin rpy="0 0 0" xyz="0.123073 -0.124046 0.090327"/>
    <parent link="base_link"/>
    <child link="motor_RightFront_1"/>
  </joint>
  <joint name="Rigid 25" type="fixed">
    <origin rpy="0 0 0" xyz="0.123073 0.126954 0.090327"/>
    <parent link="base_link"/>
    <child link="motor_LeftFront_1"/>
  </joint>
  <joint name="Rigid 26" type="fixed">
    <origin rpy="0 0 0" xyz="-0.118927 0.126954 0.090327"/>
    <parent link="base_link"/>
    <child link="motor_LeftBack_1"/>
  </joint>
  <joint name="revLB" type="continuous">
    <origin rpy="0 0 0" xyz="1.2e-05 0.04265 0.0"/>
    <parent link="motor_LeftBack_1"/>
    <child link="wheel_LeftBack_1"/>
    <axis xyz="0.0 1.0 0.0"/>
  </joint>
  <joint name="revLF" type="continuous">
    <origin rpy="0 0 0" xyz="0.0 0.04265 0.0"/>
    <parent link="motor_LeftFront_1"/>
    <child link="wheel_LeftFront_1"/>
    <axis xyz="0.0 1.0 0.0"/>
  </joint>
  <joint name="revRF" type="continuous">
    <origin rpy="0 0 0" xyz="1.2e-05 -0.04265 0.0"/>
    <parent link="motor_RightFront_1"/>
    <child link="wheel_RightFront_1"/>
    <axis xyz="0.0 1.0 -0.0"/>
  </joint>
  <joint name="revRB" type="continuous">
    <origin rpy="0 0 0" xyz="1.2e-05 -0.04265 0.0"/>
    <parent link="motor_RightBack_1"/>
    <child link="wheel_RightBack_1"/>
    <axis xyz="0.0 1.0 -0.0"/>
  </joint>
  <joint name="Rigid 31" type="fixed">
    <origin rpy="0 0 0" xyz="0.002073 0.001454 0.181327"/>
    <parent link="base_link"/>
    <child link="lidar_1"/>
  </joint>
</robot>
